(venv) root@srv863913:/opt/ayyildizhaber# export DATABASE_URL="postgresql://ayyildizhaber:$(grep DB_PASSWORD /opt/ayyildizhaber/.env | cut -d'=' -f2)@localhost/ayyildizhaber_db"
python3 -c "
from app import app, db
with app.app_context():
    db.create_all()
    print('Veritabanı hazır')
"
grep: /opt/ayyildizhaber/.env: No such file or directory
Traceback (most recent call last):
  File "/opt/ayyildizhaber/venv/lib/python3.12/site-packages/sqlalchemy/engine/base.py", line 145, in __init__
    self._dbapi_connection = engine.raw_connection()
                             ^^^^^^^^^^^^^^^^^^^^^^^
  File "/opt/ayyildizhaber/venv/lib/python3.12/site-packages/sqlalchemy/engine/base.py", line 3297, in raw_connection
    return self.pool.connect()
           ^^^^^^^^^^^^^^^^^^^
  File "/opt/ayyildizhaber/venv/lib/python3.12/site-packages/sqlalchemy/pool/base.py", line 449, in connect
    return _ConnectionFairy._checkout(self)
           ^^^^^^^^^^^^^^^^^^^^^^^^^^^^^^^^
  File "/opt/ayyildizhaber/venv/lib/python3.12/site-packages/sqlalchemy/pool/base.py", line 1264, in _checkout
    fairy = _ConnectionRecord.checkout(pool)
            ^^^^^^^^^^^^^^^^^^^^^^^^^^^^^^^^
  File "/opt/ayyildizhaber/venv/lib/python3.12/site-packages/sqlalchemy/pool/base.py", line 713, in checkout
    rec = pool._do_get()
          ^^^^^^^^^^^^^^
  File "/opt/ayyildizhaber/venv/lib/python3.12/site-packages/sqlalchemy/pool/impl.py", line 179, in _do_get
    with util.safe_reraise():
  File "/opt/ayyildizhaber/venv/lib/python3.12/site-packages/sqlalchemy/util/langhelpers.py", line 224, in __exit__
    raise exc_value.with_traceback(exc_tb)
  File "/opt/ayyildizhaber/venv/lib/python3.12/site-packages/sqlalchemy/pool/impl.py", line 177, in _do_get
    return self._create_connection()
           ^^^^^^^^^^^^^^^^^^^^^^^^^
  File "/opt/ayyildizhaber/venv/lib/python3.12/site-packages/sqlalchemy/pool/base.py", line 390, in _create_connection
    return _ConnectionRecord(self)
           ^^^^^^^^^^^^^^^^^^^^^^^
  File "/opt/ayyildizhaber/venv/lib/python3.12/site-packages/sqlalchemy/pool/base.py", line 675, in __init__
    self.__connect()
  File "/opt/ayyildizhaber/venv/lib/python3.12/site-packages/sqlalchemy/pool/base.py", line 901, in __connect
    with util.safe_reraise():
  File "/opt/ayyildizhaber/venv/lib/python3.12/site-packages/sqlalchemy/util/langhelpers.py", line 224, in __exit__
    raise exc_value.with_traceback(exc_tb)
  File "/opt/ayyildizhaber/venv/lib/python3.12/site-packages/sqlalchemy/pool/base.py", line 897, in __connect
    self.dbapi_connection = connection = pool._invoke_creator(self)
                                         ^^^^^^^^^^^^^^^^^^^^^^^^^^
  File "/opt/ayyildizhaber/venv/lib/python3.12/site-packages/sqlalchemy/engine/create.py", line 646, in connect
    return dialect.connect(*cargs, **cparams)
           ^^^^^^^^^^^^^^^^^^^^^^^^^^^^^^^^^^
  File "/opt/ayyildizhaber/venv/lib/python3.12/site-packages/sqlalchemy/engine/default.py", line 625, in connect
    return self.loaded_dbapi.connect(*cargs, **cparams)  # type: ignore[no-any-return]  # NOQA: E501
           ^^^^^^^^^^^^^^^^^^^^^^^^^^^^^^^^^^^^^^^^^^^^
  File "/opt/ayyildizhaber/venv/lib/python3.12/site-packages/psycopg2/__init__.py", line 122, in connect
    conn = _connect(dsn, connection_factory=connection_factory, **kwasync)
           ^^^^^^^^^^^^^^^^^^^^^^^^^^^^^^^^^^^^^^^^^^^^^^^^^^^^^^^^^^^^^^^
psycopg2.OperationalError: connection to server at "localhost" (::1), port 5432 failed: fe_sendauth: no password supplied


The above exception was the direct cause of the following exception:

Traceback (most recent call last):
  File "<string>", line 2, in <module>
  File "/opt/ayyildizhaber/app.py", line 55, in <module>
    db.create_all()
  File "/opt/ayyildizhaber/venv/lib/python3.12/site-packages/flask_sqlalchemy/extension.py", line 900, in create_all
    self._call_for_binds(bind_key, "create_all")
  File "/opt/ayyildizhaber/venv/lib/python3.12/site-packages/flask_sqlalchemy/extension.py", line 881, in _call_for_binds
    getattr(metadata, op_name)(bind=engine)
  File "/opt/ayyildizhaber/venv/lib/python3.12/site-packages/sqlalchemy/sql/schema.py", line 5924, in create_all
    bind._run_ddl_visitor(
  File "/opt/ayyildizhaber/venv/lib/python3.12/site-packages/sqlalchemy/engine/base.py", line 3247, in _run_ddl_visitor
    with self.begin() as conn:
  File "/usr/lib/python3.12/contextlib.py", line 137, in __enter__
    return next(self.gen)
           ^^^^^^^^^^^^^^
  File "/opt/ayyildizhaber/venv/lib/python3.12/site-packages/sqlalchemy/engine/base.py", line 3237, in begin
    with self.connect() as conn:
         ^^^^^^^^^^^^^^
  File "/opt/ayyildizhaber/venv/lib/python3.12/site-packages/sqlalchemy/engine/base.py", line 3273, in connect
    return self._connection_cls(self)
           ^^^^^^^^^^^^^^^^^^^^^^^^^^
  File "/opt/ayyildizhaber/venv/lib/python3.12/site-packages/sqlalchemy/engine/base.py", line 147, in __init__
    Connection._handle_dbapi_exception_noconnection(
  File "/opt/ayyildizhaber/venv/lib/python3.12/site-packages/sqlalchemy/engine/base.py", line 2436, in _handle_dbapi_exception_noconnection
    raise sqlalchemy_exception.with_traceback(exc_info[2]) from e
  File "/opt/ayyildizhaber/venv/lib/python3.12/site-packages/sqlalchemy/engine/base.py", line 145, in __init__
    self._dbapi_connection = engine.raw_connection()
                             ^^^^^^^^^^^^^^^^^^^^^^^
  File "/opt/ayyildizhaber/venv/lib/python3.12/site-packages/sqlalchemy/engine/base.py", line 3297, in raw_connection
    return self.pool.connect()
           ^^^^^^^^^^^^^^^^^^^
  File "/opt/ayyildizhaber/venv/lib/python3.12/site-packages/sqlalchemy/pool/base.py", line 449, in connect
    return _ConnectionFairy._checkout(self)
           ^^^^^^^^^^^^^^^^^^^^^^^^^^^^^^^^
  File "/opt/ayyildizhaber/venv/lib/python3.12/site-packages/sqlalchemy/pool/base.py", line 1264, in _checkout
    fairy = _ConnectionRecord.checkout(pool)
            ^^^^^^^^^^^^^^^^^^^^^^^^^^^^^^^^
  File "/opt/ayyildizhaber/venv/lib/python3.12/site-packages/sqlalchemy/pool/base.py", line 713, in checkout
    rec = pool._do_get()
          ^^^^^^^^^^^^^^
  File "/opt/ayyildizhaber/venv/lib/python3.12/site-packages/sqlalchemy/pool/impl.py", line 179, in _do_get
    with util.safe_reraise():
  File "/opt/ayyildizhaber/venv/lib/python3.12/site-packages/sqlalchemy/util/langhelpers.py", line 224, in __exit__
    raise exc_value.with_traceback(exc_tb)
  File "/opt/ayyildizhaber/venv/lib/python3.12/site-packages/sqlalchemy/pool/impl.py", line 177, in _do_get
    return self._create_connection()
           ^^^^^^^^^^^^^^^^^^^^^^^^^
  File "/opt/ayyildizhaber/venv/lib/python3.12/site-packages/sqlalchemy/pool/base.py", line 390, in _create_connection
    return _ConnectionRecord(self)
           ^^^^^^^^^^^^^^^^^^^^^^^
  File "/opt/ayyildizhaber/venv/lib/python3.12/site-packages/sqlalchemy/pool/base.py", line 675, in __init__
    self.__connect()
  File "/opt/ayyildizhaber/venv/lib/python3.12/site-packages/sqlalchemy/pool/base.py", line 901, in __connect
    with util.safe_reraise():
  File "/opt/ayyildizhaber/venv/lib/python3.12/site-packages/sqlalchemy/util/langhelpers.py", line 224, in __exit__
    raise exc_value.with_traceback(exc_tb)
  File "/opt/ayyildizhaber/venv/lib/python3.12/site-packages/sqlalchemy/pool/base.py", line 897, in __connect
    self.dbapi_connection = connection = pool._invoke_creator(self)
                                         ^^^^^^^^^^^^^^^^^^^^^^^^^^
  File "/opt/ayyildizhaber/venv/lib/python3.12/site-packages/sqlalchemy/engine/create.py", line 646, in connect
    return dialect.connect(*cargs, **cparams)
           ^^^^^^^^^^^^^^^^^^^^^^^^^^^^^^^^^^
  File "/opt/ayyildizhaber/venv/lib/python3.12/site-packages/sqlalchemy/engine/default.py", line 625, in connect
    return self.loaded_dbapi.connect(*cargs, **cparams)  # type: ignore[no-any-return]  # NOQA: E501
           ^^^^^^^^^^^^^^^^^^^^^^^^^^^^^^^^^^^^^^^^^^^^
  File "/opt/ayyildizhaber/venv/lib/python3.12/site-packages/psycopg2/__init__.py", line 122, in connect
    conn = _connect(dsn, connection_factory=connection_factory, **kwasync)
           ^^^^^^^^^^^^^^^^^^^^^^^^^^^^^^^^^^^^^^^^^^^^^^^^^^^^^^^^^^^^^^^
sqlalchemy.exc.OperationalError: (psycopg2.OperationalError) connection to server at "localhost" (::1), port 5432 failed: fe_sendauth: no password supplied

(Background on this error at: https://sqlalche.me/e/20/e3q8)